Traceback (most recent call last):
  File "/opt/hostedtoolcache/Python/3.12.10/x64/lib/python3.12/site-packages/jupyter_cache/executors/utils.py", line 58, in single_nb_execution
    executenb(
  File "/opt/hostedtoolcache/Python/3.12.10/x64/lib/python3.12/site-packages/nbclient/client.py", line 1319, in execute
    return NotebookClient(nb=nb, resources=resources, km=km, **kwargs).execute()
           ^^^^^^^^^^^^^^^^^^^^^^^^^^^^^^^^^^^^^^^^^^^^^^^^^^^^^^^^^^^^^^^^^^^^^
  File "/opt/hostedtoolcache/Python/3.12.10/x64/lib/python3.12/site-packages/jupyter_core/utils/__init__.py", line 165, in wrapped
    return loop.run_until_complete(inner)
           ^^^^^^^^^^^^^^^^^^^^^^^^^^^^^^
  File "/opt/hostedtoolcache/Python/3.12.10/x64/lib/python3.12/asyncio/base_events.py", line 691, in run_until_complete
    return future.result()
           ^^^^^^^^^^^^^^^
  File "/opt/hostedtoolcache/Python/3.12.10/x64/lib/python3.12/site-packages/nbclient/client.py", line 709, in async_execute
    await self.async_execute_cell(
  File "/opt/hostedtoolcache/Python/3.12.10/x64/lib/python3.12/site-packages/nbclient/client.py", line 1062, in async_execute_cell
    await self._check_raise_for_error(cell, cell_index, exec_reply)
  File "/opt/hostedtoolcache/Python/3.12.10/x64/lib/python3.12/site-packages/nbclient/client.py", line 918, in _check_raise_for_error
    raise CellExecutionError.from_cell_and_msg(cell, exec_reply_content)
nbclient.exceptions.CellExecutionError: An error occurred while executing the following cell:
------------------
import pyoptinterface as poi
from pyoptinterface import copt

model = copt.Model()
------------------


[31m---------------------------------------------------------------------------[39m
[31mRuntimeError[39m                              Traceback (most recent call last)
[36mCell[39m[36m [39m[32mIn[1][39m[32m, line 4[39m
[32m      1[39m [38;5;28;01mimport[39;00m[38;5;250m [39m[34;01mpyoptinterface[39;00m[38;5;250m [39m[38;5;28;01mas[39;00m[38;5;250m [39m[34;01mpoi[39;00m
[32m      2[39m [38;5;28;01mfrom[39;00m[38;5;250m [39m[34;01mpyoptinterface[39;00m[38;5;250m [39m[38;5;28;01mimport[39;00m copt
[32m----> [39m[32m4[39m model = [43mcopt[49m[43m.[49m[43mModel[49m[43m([49m[43m)[49m

[36mFile [39m[32m/opt/hostedtoolcache/Python/3.12.10/x64/lib/python3.12/site-packages/pyoptinterface/_src/copt.py:373[39m, in [36mModel.__init__[39m[34m(self, env)[39m
[32m    371[39m [38;5;28;01mdef[39;00m[38;5;250m [39m[34m__init__[39m([38;5;28mself[39m, env=[38;5;28;01mNone[39;00m):
[32m    372[39m     [38;5;28;01mif[39;00m env [38;5;129;01mis[39;00m [38;5;28;01mNone[39;00m:
[32m--> [39m[32m373[39m         [43minit_default_env[49m[43m([49m[43m)[49m
[32m    374[39m         env = DEFAULT_ENV
[32m    375[39m     [38;5;28msuper[39m().[34m__init__[39m(env)

[36mFile [39m[32m/opt/hostedtoolcache/Python/3.12.10/x64/lib/python3.12/site-packages/pyoptinterface/_src/copt.py:83[39m, in [36minit_default_env[39m[34m()[39m
[32m     81[39m [38;5;28;01mglobal[39;00m DEFAULT_ENV
[32m     82[39m [38;5;28;01mif[39;00m DEFAULT_ENV [38;5;129;01mis[39;00m [38;5;28;01mNone[39;00m:
[32m---> [39m[32m83[39m     DEFAULT_ENV = [43mEnv[49m[43m([49m[43m)[49m

[31mRuntimeError[39m: COPT library is not loaded

