Traceback (most recent call last):
  File "/opt/hostedtoolcache/Python/3.12.8/x64/lib/python3.12/site-packages/jupyter_cache/executors/utils.py", line 58, in single_nb_execution
    executenb(
  File "/opt/hostedtoolcache/Python/3.12.8/x64/lib/python3.12/site-packages/nbclient/client.py", line 1319, in execute
    return NotebookClient(nb=nb, resources=resources, km=km, **kwargs).execute()
           ^^^^^^^^^^^^^^^^^^^^^^^^^^^^^^^^^^^^^^^^^^^^^^^^^^^^^^^^^^^^^^^^^^^^^
  File "/opt/hostedtoolcache/Python/3.12.8/x64/lib/python3.12/site-packages/jupyter_core/utils/__init__.py", line 165, in wrapped
    return loop.run_until_complete(inner)
           ^^^^^^^^^^^^^^^^^^^^^^^^^^^^^^
  File "/opt/hostedtoolcache/Python/3.12.8/x64/lib/python3.12/asyncio/base_events.py", line 686, in run_until_complete
    return future.result()
           ^^^^^^^^^^^^^^^
  File "/opt/hostedtoolcache/Python/3.12.8/x64/lib/python3.12/site-packages/nbclient/client.py", line 709, in async_execute
    await self.async_execute_cell(
  File "/opt/hostedtoolcache/Python/3.12.8/x64/lib/python3.12/site-packages/nbclient/client.py", line 1062, in async_execute_cell
    await self._check_raise_for_error(cell, cell_index, exec_reply)
  File "/opt/hostedtoolcache/Python/3.12.8/x64/lib/python3.12/site-packages/nbclient/client.py", line 918, in _check_raise_for_error
    raise CellExecutionError.from_cell_and_msg(cell, exec_reply_content)
nbclient.exceptions.CellExecutionError: An error occurred while executing the following cell:
------------------
model = highs.Model()

x = model.add_m_variables(N)

A = np.eye(N)
b_ub = np.ones(N)
b_lb = np.ones(N)

model.add_m_linear_constraints(A, x, poi.Leq, b_ub)
model.add_m_linear_constraints(A, x, poi.Geq, b_lb)

model.set_objective(poi.quicksum(x))

model.optimize()
------------------

----- stdout -----
Running HiGHS 1.9.0 (git hash: 66f735e): Copyright (c) 2024 HiGHS under MIT licence terms
------------------

[0;31m---------------------------------------------------------------------------[0m
[0;31mModuleNotFoundError[0m                       Traceback (most recent call last)
Cell [0;32mIn[6], line 9[0m
[1;32m      6[0m b_ub [38;5;241m=[39m np[38;5;241m.[39mones(N)
[1;32m      7[0m b_lb [38;5;241m=[39m np[38;5;241m.[39mones(N)
[0;32m----> 9[0m [43mmodel[49m[38;5;241;43m.[39;49m[43madd_m_linear_constraints[49m[43m([49m[43mA[49m[43m,[49m[43m [49m[43mx[49m[43m,[49m[43m [49m[43mpoi[49m[38;5;241;43m.[39;49m[43mLeq[49m[43m,[49m[43m [49m[43mb_ub[49m[43m)[49m
[1;32m     10[0m model[38;5;241m.[39madd_m_linear_constraints(A, x, poi[38;5;241m.[39mGeq, b_lb)
[1;32m     12[0m model[38;5;241m.[39mset_objective(poi[38;5;241m.[39mquicksum(x))

File [0;32m/opt/hostedtoolcache/Python/3.12.8/x64/lib/python3.12/site-packages/pyoptinterface/_src/matrix.py:35[0m, in [0;36madd_matrix_constraints[0;34m(model, A, x, sense, b)[0m
[1;32m     26[0m [38;5;250m[39m[38;5;124;03m"""[39;00m
[1;32m     27[0m [38;5;124;03madd constraints Ax <= / = / >= b[39;00m
[1;32m     28[0m 
[0;32m   (...)[0m
[1;32m     32[0m [38;5;124;03mb is an iterable of values or a single scalar[39;00m
[1;32m     33[0m [38;5;124;03m"""[39;00m
[1;32m     34[0m [38;5;28;01mimport[39;00m[38;5;250m [39m[38;5;21;01mnumpy[39;00m[38;5;250m [39m[38;5;28;01mas[39;00m[38;5;250m [39m[38;5;21;01mnp[39;00m
[0;32m---> 35[0m [38;5;28;01mfrom[39;00m[38;5;250m [39m[38;5;21;01mscipy[39;00m[38;5;21;01m.[39;00m[38;5;21;01msparse[39;00m[38;5;250m [39m[38;5;28;01mimport[39;00m sparray
[1;32m     37[0m is_ndarray [38;5;241m=[39m [38;5;28misinstance[39m(A, np[38;5;241m.[39mndarray)
[1;32m     38[0m is_sparse [38;5;241m=[39m [38;5;28misinstance[39m(A, sparray)

[0;31mModuleNotFoundError[0m: No module named 'scipy'

